Workbook

Sheet 722講義室
B1: チーム | C1: 発表時間(6分24秒→624と入力) | D1: プレゼン構成 | E1: 客観性・根拠性 | F1: 資料 | G1: 態度・話し方 | J1: 質疑応答 | K1: メモ
B2: =まとめ!D2 -> 16 | G2: =まとめ!A2 -> 24G1009 | H2: =まとめ!B2 -> 井澤 晴空
G3: =まとめ!A3 -> 24G1063 | H3: =まとめ!B3 -> 佐藤 碧唯
G4: =まとめ!A4 -> 24G1073 | H4: =まとめ!B4 -> 清水 優花
B5: =まとめ!D5 -> 34 | G5: =まとめ!A5 -> 24G1072 | H5: =まとめ!B5 -> 澁谷 祐汰
G6: =まとめ!A6 -> 24G1102 | H6: =まとめ!B6 -> 冨田 一之心
G7: =まとめ!A7 -> 24G1107 | H7: =まとめ!B7 -> 野口 滉太
B8: =まとめ!D8 -> 14 | G8: =まとめ!A8 -> 24G1094 | H8: =まとめ!B8 -> 斎藤 拓海
G9: =まとめ!A9 -> 24G1115 | H9: =まとめ!B9 -> 比志 佳代
G10: =まとめ!A10 -> 24G1126 | H10: =まとめ!B10 -> 三島 遙玖
B11: =まとめ!D11 -> 32 | G11: =まとめ!A11 -> 24G1035 | H11: =まとめ!B11 -> 尾添 遼太
G12: =まとめ!A12 -> 24G1056 | H12: =まとめ!B12 -> 慶田 優
G13: =まとめ!A13 -> 24G1101 | H13: =まとめ!B13 -> 飛田 啓斗
B14: =まとめ!D14 -> 25 | G14: =まとめ!A14 -> 24G1067 | H14: =まとめ!B14 -> 佐野 皓紀
G15: =まとめ!A15 -> 24G1119 | H15: =まとめ!B15 -> 福田 人和
G16: =まとめ!A16 -> 24G1123 | H16: =まとめ!B16 -> 真下 詩生
B17: =まとめ!D17 -> 24 | G17: =まとめ!A17 -> 24G1039 | H17: =まとめ!B17 -> 金海 聖人
G18: =まとめ!A18 -> 24G1071 | H18: =まとめ!B18 -> 柴崎 悠瑞
G19: =まとめ!A19 -> 24G1114 | H19: =まとめ!B19 -> 日暮 太志
B20: =まとめ!D20 -> 1 | G20: =まとめ!A20 -> 24G1041 | H20: =まとめ!B20 -> 金澤 開晴
G21: =まとめ!A21 -> 24G1043 | H21: =まとめ!B21 -> 加茂 釉芭
G22: =まとめ!A22 -> 24G1121 | H22: =まとめ!B22 -> ベ シウ
B23: =まとめ!D23 -> 29 | G23: =まとめ!A23 -> 24G1001 | H23: =まとめ!B23 -> 相京 航汰
G24: =まとめ!A24 -> 24G1091 | H24: =まとめ!B24 -> 田代 壮
G25: =まとめ!A25 -> 24G1144 | H25: =まとめ!B25 -> 渡邉 晃大
B26: =まとめ!D26 -> 19 | G26: =まとめ!A26 -> 24G1015 | H26: =まとめ!B26 -> 市瀬 広樹
G27: =まとめ!A27 -> 24G1029 | H27: =まとめ!B27 -> 大嶺 壮志
G28: =まとめ!A28 -> 24G1082 | H28: =まとめ!B28 -> 清吾 友美
B29: =まとめ!D29 -> 12 | G29: =まとめ!A29 -> 24G1079 | H29: =まとめ!B29 -> 鈴木 涼斗
G30: =まとめ!A30 -> 24G1113 | H30: =まとめ!B30 -> 坂 泰河
G31: =まとめ!A31 -> 24G1128 | H31: =まとめ!B31 -> 三原 千周
B32: =まとめ!D32 -> 26 | G32: =まとめ!A32 -> 24G1040 | H32: =まとめ!B32 -> 金枝 優介
G33: =まとめ!A33 -> 24G1074 | H33: =まとめ!B33 -> 荘司 あかね
G34: =まとめ!A34 -> 24G1125 | H34: =まとめ!B34 -> 三芝 空音

Sheet 731講義室
B1: チーム | C1: 発表時間(6分24秒→624と入力) | D1: プレゼン構成 | E1: 客観性・根拠性 | F1: 資料 | G1: 態度・話し方 | J1: 質疑応答 | K1: メモ
B2: =まとめ!D35 -> 10 | G2: =まとめ!A35 -> 24G1012 | H2: =まとめ!B35 -> 石坂 琢磨
G3: =まとめ!A36 -> 24G1032 | H3: =まとめ!B36 -> 荻野 泰地
G4: =まとめ!A37 -> 24G1146 | H4: =まとめ!B37 -> 渡邉 那音
B5: =まとめ!D38 -> 37 | G5: =まとめ!A38 -> 24G1002 | H5: =まとめ!B38 -> 秋葉 聖哉
G6: =まとめ!A39 -> 24G1109 | H6: =まとめ!B39 -> 林田 裕太朗
G7: =まとめ!A40 -> 24G1124 | H7: =まとめ!B40 -> 三木 俊英
B8: =まとめ!D41 -> 33 | G8: =まとめ!A41 -> 24G1016 | H8: =まとめ!B41 -> 伊藤 脩
G9: =まとめ!A42 -> 24G1031 | H9: =まとめ!B42 -> 小川 泰生
G10: =まとめ!A43 -> 24G1083 | H10: =まとめ!B43 -> 清宮 俊
B11: =まとめ!D44 -> 42 | G11: =まとめ!A44 -> 24G1005 | H11: =まとめ!B44 -> 淺沼 龍太
G12: =まとめ!A45 -> 24G1078 | H12: =まとめ!B45 -> 鈴木 琉
G13: =まとめ!A46 -> 24G1111 | H13: =まとめ!B46 -> 原 颯登
B14: =まとめ!D47 -> 41 | G14: =まとめ!A47 -> 24G1023 | H14: =まとめ!B47 -> 上原 拓海
G15: =まとめ!A48 -> 24G1042 | H15: =まとめ!B48 -> 鎌田 素木
G16: =まとめ!A49 -> 24G1100 | H16: =まとめ!B49 -> 戸田 健太
B17: =まとめ!D50 -> 22 | G17: =まとめ!A50 -> 24G1068 | H17: =まとめ!B50 -> 沢田 迅
G18: =まとめ!A51 -> 24G1099 | H18: =まとめ!B51 -> 寺田 幸正
G19: =まとめ!A52 -> 24G1142 | H19: =まとめ!B52 -> 米原 亙
B20: =まとめ!D53 -> 3 | G20: =まとめ!A53 -> 24G1007 | H20: =まとめ!B53 -> 網中 洲
G21: =まとめ!A54 -> 24G1018 | H21: =まとめ!B54 -> 岩岡 悠衣花
G22: =まとめ!A55 -> 24G1077 | H22: =まとめ!B55 -> 鈴木 希歩
B23: =まとめ!D56 -> 27 | G23: =まとめ!A56 -> 24G1037 | H23: =まとめ!B56 -> 小山 絢
G24: =まとめ!A57 -> 24G1051 | H24: =まとめ!B57 -> 久峩 丈
G25: =まとめ!A58 -> 24G1059 | H25: =まとめ!B58 -> 小松 遼翔
B26: =まとめ!D59 -> 31 | G26: =まとめ!A59 -> 24G1025 | H26: =まとめ!B59 -> 生方 淳裕
G27: =まとめ!A60 -> 24G1140 | H27: =まとめ!B60 -> 吉岡 優
G28: =まとめ!A61 -> 24G1141 | H28: =まとめ!B61 -> 米津 はるか
B29: =まとめ!D62 -> 7 | G29: =まとめ!A62 -> 24G1017 | H29: =まとめ!B62 -> 井上 悠
G30: =まとめ!A63 -> 24G1022 | H30: =まとめ!B63 -> 上坂 大河
G31: =まとめ!A64 -> 24G1096 | H31: =まとめ!B64 -> 堤 千真
B32: =まとめ!D65 -> 4 | G32: =まとめ!A65 -> 24G1061 | H32: =まとめ!B65 -> 酒井 睦基
G33: =まとめ!A66 -> 24G1089 | H33: =まとめ!B66 -> 武本 龍
G34: =まとめ!A67 -> 24G1122 | H34: =まとめ!B67 -> 細澤 悠真

Sheet 732講義室
B1: チーム | C1: 発表時間(6分24秒→624と入力) | D1: プレゼン構成 | E1: 客観性・根拠性 | F1: 資料 | G1: 態度・話し方 | J1: 質疑応答 | K1: メモ
B2: =まとめ!D68 -> 28 | G2: =まとめ!A68 -> 24G1105 | H2: =まとめ!B68 -> 長妻 冬威
G3: =まとめ!A69 -> 24G1110 | H3: =まとめ!B69 -> 葉山 颯太
G4: =まとめ!A70 -> 24G1127 | H4: =まとめ!B70 -> 水田 悠斗
B5: =まとめ!D71 -> 39 | G5: =まとめ!A71 -> 24G1011 | H5: =まとめ!B71 -> 石川 敏伸
G6: =まとめ!A72 -> 24G1044 | H6: =まとめ!B72 -> 河井 晴仁
G7: =まとめ!A73 -> 24G1118 | H7: =まとめ!B73 -> 平峯 佑亮
B8: =まとめ!D74 -> 21 | G8: =まとめ!A74 -> 24G1013 | H8: =まとめ!B74 -> 石崎 一葉
G9: =まとめ!A75 -> 24G1070 | H9: =まとめ!B75 -> 重冨 陽人
G10: =まとめ!A76 -> 24G1092 | H10: =まとめ!B76 -> 田中 斗百矢
B11: =まとめ!D77 -> 13 | G11: =まとめ!A77 -> 24G1024 | H11: =まとめ!B77 -> 鵜澤 勇希
G12: =まとめ!A78 -> 24G1088 | H12: =まとめ!B78 -> 武井 佑樹
G13: =まとめ!A79 -> 24G1095 | H13: =まとめ!B79 -> 塚田 快音
B14: =まとめ!D80 -> 8 | G14: =まとめ!A80 -> 24G1045 | H14: =まとめ!B80 -> 川畑 吏生
G15: =まとめ!A81 -> 24G1087 | H15: =まとめ!B81 -> 鷹觜 隼
G16: =まとめ!A82 -> 24G1143 | H16: =まとめ!B82 -> 渡辺 一丸
B17: =まとめ!D83 -> 23 | G17: =まとめ!A83 -> 24G1038 | H17: =まとめ!B83 -> 片岡 聖
G18: =まとめ!A84 -> 24G1075 | H18: =まとめ!B84 -> 地曵 賢人
G19: =まとめ!A85 -> 24G1131 | H19: =まとめ!B85 -> 御代川 稜
B20: =まとめ!D86 -> 30 | G20: =まとめ!A86 -> 24G1033 | H20: =まとめ!B86 -> 荻野 真矢
G21: =まとめ!A87 -> 24G1034 | H21: =まとめ!B87 -> 小口 悠翔
G22: =まとめ!A88 -> 24G1060 | H22: =まとめ!B88 -> 齊藤 銀二
B23: =まとめ!D89 -> 35 | G23: =まとめ!A89 -> 24G1008 | H23: =まとめ!B89 -> 飯田 雄之介
G24: =まとめ!A90 -> 24G1030 | H24: =まとめ!B90 -> 大室 信明
G25: =まとめ!A91 -> 24G1097 | H25: =まとめ!B91 -> 坪井 龍之介
B26: =まとめ!D92 -> 6 | G26: =まとめ!A92 -> 24G1019 | H26: =まとめ!B92 -> 岩永 幹
G27: =まとめ!A93 -> 24G1086 | H27: =まとめ!B93 -> 楚山 聖七
G28: =まとめ!A94 -> 24G1116 | H28: =まとめ!B94 -> 平岡 祐典
B29: =まとめ!D95 -> 11 | G29: =まとめ!A95 -> 24G1004 | H29: =まとめ!B95 -> 浅田 和奏
G30: =まとめ!A96 -> 24G1085 | H30: =まとめ!B96 -> 瀬部 直人
G31: =まとめ!A97 -> 24G1090 | H31: =まとめ!B97 -> 田子 隼斗
B32: =まとめ!D98 -> 17 | G32: =まとめ!A98 -> 24G1020 | H32: =まとめ!B98 -> 岩波 晃士
G33: =まとめ!A99 -> 24G1080 | H33: =まとめ!B99 -> 須磨 奏斗
G34: =まとめ!A100 -> 24G1084 | H34: =まとめ!B100 -> 関屋 咲希

Sheet 733講義室
B1: チーム | C1: 発表時間(6分24秒→624と入力) | D1: プレゼン構成 | E1: 客観性・根拠性 | F1: 資料 | G1: 態度・話し方 | J1: 質疑応答 | K1: メモ
B2: =まとめ!D114 -> 2 | G2: =まとめ!A114 -> 24G1046 | H2: =まとめ!B114 -> 川又 快斗
G3: =まとめ!A115 -> 24G1053 | H3: =まとめ!B115 -> 熊本 朱純
G4: =まとめ!A116 -> 24G1133 | H4: =まとめ!B116 -> 安尾 晃貴
B5: =まとめ!D117 -> 38 | G5: =まとめ!A117 -> 24G1028 | H5: =まとめ!B117 -> 大關 宗一郎
G6: =まとめ!A118 -> 24G1050 | H6: =まとめ!B118 -> 木村 優斗
G7: =まとめ!A119 -> 24G1108 | H7: =まとめ!B119 -> 長谷川 空
B8: =まとめ!D120 -> 9 | G8: =まとめ!A120 -> 24G1052 | H8: =まとめ!B120 -> 久家 力孔
G9: =まとめ!A121 -> 24G1098 | H9: =まとめ!B121 -> 手代木 巧
G10: =まとめ!A122 -> 24G1145 | H10: =まとめ!B122 -> 渡邊 乃斗
B11: =まとめ!D123 -> 18 | G11: =まとめ!A123 -> 24G1064 | H11: =まとめ!B123 -> 佐藤 陽空
G12: =まとめ!A124 -> 24G1076 | H12: =まとめ!B124 -> 末松 勇輝
G13: =まとめ!A125 -> 24G1138 | H13: =まとめ!B125 -> 山下 輝明
B14: =まとめ!D126 -> 20 | G14: =まとめ!A126 -> 24G1106 | H14: =まとめ!B126 -> 根本 愛莉咲
G15: =まとめ!A127 -> 24G1117 | H15: =まとめ!B127 -> 平川 ケン
G16: =まとめ!A128 -> 24G1130 | H16: =まとめ!B128 -> 宮崎 良真
B17: =まとめ!D129 -> 5 | G17: =まとめ!A129 -> 24G1057 | H17: =まとめ!B129 -> 此上 健友
G18: =まとめ!A130 -> 24G1066 | H18: =まとめ!B130 -> 佐藤 琉惺
G19: =まとめ!A131 -> 24G1120 | H19: =まとめ!B131 -> 藤本 眞輝
B20: =まとめ!D132 -> 36 | G20: =まとめ!A132 -> 24G1006 | H20: =まとめ!B132 -> 足立 輝弥
G21: =まとめ!A133 -> 24G1014 | H21: =まとめ!B133 -> 市川 瑠生
G22: =まとめ!A134 -> 24G1103 | H22: =まとめ!B134 -> 中野 詩音
B23: =まとめ!D135 -> 15 | G23: =まとめ!A135 -> 24G1003 | H23: =まとめ!B135 -> 麻田 竜希
G24: =まとめ!A136 -> 24G1010 | H24: =まとめ!B136 -> 石川 司理
G25: =まとめ!A137 -> 24G1055 | H25: =まとめ!B137 -> 桑原 拓也
B26: =まとめ!D138 -> 40 | G26: =まとめ!A138 -> 24G1021 | H26: =まとめ!B138 -> 宇井 祐真
G27: =まとめ!A139 -> 24G1026 | H27: =まとめ!B139 -> 梅野 大誠
G28: =まとめ!A140 -> 24G1136 | H28: =まとめ!B140 -> 山口 侑希
B29: 44 | G29: 2131071 | H29: 佐々木 慎吾
G30: 2231119 | H30: 林 拓人
G31: 2231161 | H31: 枠谷 友太
G32: 24G1081 | H32: 諏訪 大翔
G33: 24G1139 | H33: 山根 竜希
B34: 43 | G34: 2231108 | H34: 長田 慎太郎
G35: 2231037 | H35: 大澤 亮哉
G36: 2231138 | H36: 水川 脩平
G37: 2331138 | H37: 丸山 大晴
G38: 2331143 | H38: 宮崎 基
G39: 24G1036 | H39: 織田 楽文

Sheet まとめ
A1: 学籍番号 | B1: 氏名 | C1: 講義 | D1: チーム | E1: 参考 | F1: 講義室 | G1: 合計点 | H1: 発表時間 | I1: プレゼン構成 | J1: 客観性・根拠性 | K1: 資料 | L1: 態度・話し方 | M1: 質疑応答 | N1: 発表時間2 | O1: 倍率 | P1: プレゼン構成3 | Q1: 客観性・根拠性4 | R1: 資料5 | S1: 態度・話し方6 | T1: 質疑応答7
A2: 24G1009 | B2: 井澤 晴空 | C2: ハッカソン２ | D2: 16 | E2: 41 | F2: 722講義室 | G2: =SUM($P2:$T2)*$O2 -> 0 | H2: =VLOOKUP($D2,'722講義室'!$B$2:$F$34,2,FALSE) -> 0 | I2: =VLOOKUP($D2,'722講義室'!$B$2:$F$34,3,FALSE) -> 0 | J2: =VLOOKUP($D2,'722講義室'!$B$2:$F$34,4,FALSE) -> 0 | K2: =VLOOKUP($D2,'722講義室'!$B$2:$F$34,5,FALSE) -> 0 | L2: =VLOOKUP($A2,'722講義室'!$G$2:$I$34,3,FALSE) -> 0 | M2: =VLOOKUP($D2,'722講義室'!$B$2:$J$34,9,FALSE) -> 0 | N2: =TIME(0, INT($H2/100), MOD($H2,100)) -> 0 | O2: {=_xlfn.LET( _xlpm.t, TIME(0, INT($H2/100), MOD($H2,100)), _xlfn.IFS( AND(_xlpm.t>=TIME(0,7,1), _xlpm.t<=TIME(0,8,19)), 1, AND(_xlpm.t>=TIME(0,6,1), _xlpm.t<=TIME(0,7,0)), 0.8, AND(_xlpm.t>=TIME(0,8,20), _xlpm.t<=TIME(0,8,59)), 0.8, AND(_xlpm.t>=TIME(0,5,1), _xlpm.t<=TIME(0,6,0)), 0.5, AND(_xlpm.t>=TIME(0,9,0), _xlpm.t<=TIME(0,9,59)), 0.5, TRUE, 0.3 ) )} -> 0.3 | P2: =VALUE(LEFT(I2,1)) -> 0 | Q2: =VALUE(LEFT(J2,1)) -> 0 | R2: =VALUE(LEFT(K2,1)) -> 0 | S2: =VALUE(LEFT(L2,1)) -> 0 | T2: =VALUE(LEFT(M2,1)) -> 0
A3: 24G1063 | B3: 佐藤 碧唯 | C3: ハッカソン２ | D3: 16 | E3: 41 | F3: 722講義室 | G3: =SUM($P3:$T3)*$O3 -> 0 | H3: =VLOOKUP($D3,'722講義室'!$B$2:$F$34,2,FALSE) -> 0 | I3: =VLOOKUP($D3,'722講義室'!$B$2:$F$34,3,FALSE) -> 0 | J3: =VLOOKUP($D3,'722講義室'!$B$2:$F$34,4,FALSE) -> 0 | K3: =VLOOKUP($D3,'722講義室'!$B$2:$F$34,5,FALSE) -> 0 | L3: =VLOOKUP($A3,'722講義室'!$G$2:$I$34,3,FALSE) -> 0 | M3: =VLOOKUP($D3,'722講義室'!$B$2:$J$34,9,FALSE) -> 0 | N3: =TIME(0, INT($H3/100), MOD($H3,100)) -> 0 | O3: {=_xlfn.LET( _xlpm.t, TIME(0, INT($H3/100), MOD($H3,100)), _xlfn.IFS( AND(_xlpm.t>=TIME(0,7,1), _xlpm.t<=TIME(0,8,19)), 1, AND(_xlpm.t>=TIME(0,6,1), _xlpm.t<=TIME(0,7,0)), 0.8, AND(_xlpm.t>=TIME(0,8,20), _xlpm.t<=TIME(0,8,59)), 0.8, AND(_xlpm.t>=TIME(0,5,1), _xlpm.t<=TIME(0,6,0)), 0.5, AND(_xlpm.t>=TIME(0,9,0), _xlpm.t<=TIME(0,9,59)), 0.5, TRUE, 0.3 ) )} -> 0.3 | P3: =VALUE(LEFT(I3,1)) -> 0 | Q3: =VALUE(LEFT(J3,1)) -> 0 | R3: =VALUE(LEFT(K3,1)) -> 0 | S3: =VALUE(LEFT(L3,1)) -> 0 | T3: =VALUE(LEFT(M3,1)) -> 0
A4: 24G1073 | B4: 清水 優花 | C4: ハッカソン２ | D4: 16 | E4: 41 | F4: 722講義室 | G4: =SUM($P4:$T4)*$O4 -> 0 | H4: =VLOOKUP($D4,'722講義室'!$B$2:$F$34,2,FALSE) -> 0 | I4: =VLOOKUP($D4,'722講義室'!$B$2:$F$34,3,FALSE) -> 0 | J4: =VLOOKUP($D4,'722講義室'!$B$2:$F$34,4,FALSE) -> 0 | K4: =VLOOKUP($D4,'722講義室'!$B$2:$F$34,5,FALSE) -> 0 | L4: =VLOOKUP($A4,'722講義室'!$G$2:$I$34,3,FALSE) -> 0 | M4: =VLOOKUP($D4,'722講義室'!$B$2:$J$34,9,FALSE) -> 0 | N4: =TIME(0, INT($H4/100), MOD($H4,100)) -> 0 | O4: {=_xlfn.LET( _xlpm.t, TIME(0, INT($H4/100), MOD($H4,100)), _xlfn.IFS( AND(_xlpm.t>=TIME(0,7,1), _xlpm.t<=TIME(0,8,19)), 1, AND(_xlpm.t>=TIME(0,6,1), _xlpm.t<=TIME(0,7,0)), 0.8, AND(_xlpm.t>=TIME(0,8,20), _xlpm.t<=TIME(0,8,59)), 0.8, AND(_xlpm.t>=TIME(0,5,1), _xlpm.t<=TIME(0,6,0)), 0.5, AND(_xlpm.t>=TIME(0,9,0), _xlpm.t<=TIME(0,9,59)), 0.5, TRUE, 0.3 ) )} -> 0.3 | P4: =VALUE(LEFT(I4,1)) -> 0 | Q4: =VALUE(LEFT(J4,1)) -> 0 | R4: =VALUE(LEFT(K4,1)) -> 0 | S4: =VALUE(LEFT(L4,1)) -> 0 | T4: =VALUE(LEFT(M4,1)) -> 0
A5: 24G1072 | B5: 澁谷 祐汰 | C5: ハッカソン２ | D5: 34 | E5: 38 | F5: 722講義室 | G5: =SUM($P5:$T5)*$O5 -> 0 | H5: =VLOOKUP($D5,'722講義室'!$B$2:$F$34,2,FALSE) -> 0 | I5: =VLOOKUP($D5,'722講義室'!$B$2:$F$34,3,FALSE) -> 0 | J5: =VLOOKUP($D5,'722講義室'!$B$2:$F$34,4,FALSE) -> 0 | K5: =VLOOKUP($D5,'722講義室'!$B$2:$F$34,5,FALSE) -> 0 | L5: =VLOOKUP($A5,'722講義室'!$G$2:$I$34,3,FALSE) -> 0 | M5: =VLOOKUP($D5,'722講義室'!$B$2:$J$34,9,FALSE) -> 0 | N5: =TIME(0, INT($H5/100), MOD($H5,100)) -> 0 | O5: {=_xlfn.LET( _xlpm.t, TIME(0, INT($H5/100), MOD($H5,100)), _xlfn.IFS( AND(_xlpm.t>=TIME(0,7,1), _xlpm.t<=TIME(0,8,19)), 1, AND(_xlpm.t>=TIME(0,6,1), _xlpm.t<=TIME(0,7,0)), 0.8, AND(_xlpm.t>=TIME(0,8,20), _xlpm.t<=TIME(0,8,59)), 0.8, AND(_xlpm.t>=TIME(0,5,1), _xlpm.t<=TIME(0,6,0)), 0.5, AND(_xlpm.t>=TIME(0,9,0), _xlpm.t<=TIME(0,9,59)), 0.5, TRUE, 0.3 ) )} -> 0.3 | P5: =VALUE(LEFT(I5,1)) -> 0 | Q5: =VALUE(LEFT(J5,1)) -> 0 | R5: =VALUE(LEFT(K5,1)) -> 0 | S5: =VALUE(LEFT(L5,1)) -> 0 | T5: =VALUE(LEFT(M5,1)) -> 0
A6: 24G1102 | B6: 冨田 一之心 | C6: ハッカソン２ | D6: 34 | E6: 38 | F6: 722講義室 | G6: =SUM($P6:$T6)*$O6 -> 0 | H6: =VLOOKUP($D6,'722講義室'!$B$2:$F$34,2,FALSE) -> 0 | I6: =VLOOKUP($D6,'722講義室'!$B$2:$F$34,3,FALSE) -> 0 | J6: =VLOOKUP($D6,'722講義室'!$B$2:$F$34,4,FALSE) -> 0 | K6: =VLOOKUP($D6,'722講義室'!$B$2:$F$34,5,FALSE) -> 0 | L6: =VLOOKUP($A6,'722講義室'!$G$2:$I$34,3,FALSE) -> 0 | M6: =VLOOKUP($D6,'722講義室'!$B$2:$J$34,9,FALSE) -> 0 | N6: =TIME(0, INT($H6/100), MOD($H6,100)) -> 0 | O6: {=_xlfn.LET( _xlpm.t, TIME(0, INT($H6/100), MOD($H6,100)), _xlfn.IFS( AND(_xlpm.t>=TIME(0,7,1), _xlpm.t<=TIME(0,8,19)), 1, AND(_xlpm.t>=TIME(0,6,1), _xlpm.t<=TIME(0,7,0)), 0.8, AND(_xlpm.t>=TIME(0,8,20), _xlpm.t<=TIME(0,8,59)), 0.8, AND(_xlpm.t>=TIME(0,5,1), _xlpm.t<=TIME(0,6,0)), 0.5, AND(_xlpm.t>=TIME(0,9,0), _xlpm.t<=TIME(0,9,59)), 0.5, TRUE, 0.3 ) )} -> 0.3 | P6: =VALUE(LEFT(I6,1)) -> 0 | Q6: =VALUE(LEFT(J6,1)) -> 0 | R6: =VALUE(LEFT(K6,1)) -> 0 | S6: =VALUE(LEFT(L6,1)) -> 0 | T6: =VALUE(LEFT(M6,1)) -> 0
A7: 24G1107 | B7: 野口 滉太 | C7: ハッカソン２ | D7: 34 | E7: 38 | F7: 722講義室 | G7: =SUM($P7:$T7)*$O7 -> 0 | H7: =VLOOKUP($D7,'722講義室'!$B$2:$F$34,2,FALSE) -> 0 | I7: =VLOOKUP($D7,'722講義室'!$B$2:$F$34,3,FALSE) -> 0 | J7: =VLOOKUP($D7,'722講義室'!$B$2:$F$34,4,FALSE) -> 0 | K7: =VLOOKUP($D7,'722講義室'!$B$2:$F$34,5,FALSE) -> 0 | L7: =VLOOKUP($A7,'722講義室'!$G$2:$I$34,3,FALSE) -> 0 | M7: =VLOOKUP($D7,'722講義室'!$B$2:$J$34,9,FALSE) -> 0 | N7: =TIME(0, INT($H7/100), MOD($H7,100)) -> 0 | O7: {=_xlfn.LET( _xlpm.t, TIME(0, INT($H7/100), MOD($H7,100)), _xlfn.IFS( AND(_xlpm.t>=TIME(0,7,1), _xlpm.t<=TIME(0,8,19)), 1, AND(_xlpm.t>=TIME(0,6,1), _xlpm.t<=TIME(0,7,0)), 0.8, AND(_xlpm.t>=TIME(0,8,20), _xlpm.t<=TIME(0,8,59)), 0.8, AND(_xlpm.t>=TIME(0,5,1), _xlpm.t<=TIME(0,6,0)), 0.5, AND(_xlpm.t>=TIME(0,9,0), _xlpm.t<=TIME(0,9,59)), 0.5, TRUE, 0.3 ) )} -> 0.3 | P7: =VALUE(LEFT(I7,1)) -> 0 | Q7: =VALUE(LEFT(J7,1)) -> 0 | R7: =VALUE(LEFT(K7,1)) -> 0 | S7: =VALUE(LEFT(L7,1)) -> 0 | T7: =VALUE(LEFT(M7,1)) -> 0
A8: 24G1094 | B8: 斎藤 拓海 | C8: ハッカソン２ | D8: 14 | E8: 35 | F8: 722講義室 | G8: =SUM($P8:$T8)*$O8 -> 0 | H8: =VLOOKUP($D8,'722講義室'!$B$2:$F$34,2,FALSE) -> 0 | I8: =VLOOKUP($D8,'722講義室'!$B$2:$F$34,3,FALSE) -> 0 | J8: =VLOOKUP($D8,'722講義室'!$B$2:$F$34,4,FALSE) -> 0 | K8: =VLOOKUP($D8,'722講義室'!$B$2:$F$34,5,FALSE) -> 0 | L8: =VLOOKUP($A8,'722講義室'!$G$2:$I$34,3,FALSE) -> 0 | M8: =VLOOKUP($D8,'722講義室'!$B$2:$J$34,9,FALSE) -> 0 | N8: =TIME(0, INT($H8/100), MOD($H8,100)) -> 0 | O8: {=_xlfn.LET( _xlpm.t, TIME(0, INT($H8/100), MOD($H8,100)), _xlfn.IFS( AND(_xlpm.t>=TIME(0,7,1), _xlpm.t<=TIME(0,8,19)), 1, AND(_xlpm.t>=TIME(0,6,1), _xlpm.t<=TIME(0,7,0)), 0.8, AND(_xlpm.t>=TIME(0,8,20), _xlpm.t<=TIME(0,8,59)), 0.8, AND(_xlpm.t>=TIME(0,5,1), _xlpm.t<=TIME(0,6,0)), 0.5, AND(_xlpm.t>=TIME(0,9,0), _xlpm.t<=TIME(0,9,59)), 0.5, TRUE, 0.3 ) )} -> 0.3 | P8: =VALUE(LEFT(I8,1)) -> 0 | Q8: =VALUE(LEFT(J8,1)) -> 0 | R8: =VALUE(LEFT(K8,1)) -> 0 | S8: =VALUE(LEFT(L8,1)) -> 0 | T8: =VALUE(LEFT(M8,1)) -> 0
A9: 24G1115 | B9: 比志 佳代 | C9: ハッカソン２ | D9: 14 | E9: 35 | F9: 722講義室 | G9: =SUM($P9:$T9)*$O9 -> 0 | H9: =VLOOKUP($D9,'722講義室'!$B$2:$F$34,2,FALSE) -> 0 | I9: =VLOOKUP($D9,'722講義室'!$B$2:$F$34,3,FALSE) -> 0 | J9: =VLOOKUP($D9,'722講義室'!$B$2:$F$34,4,FALSE) -> 0 | K9: =VLOOKUP($D9,'722講義室'!$B$2:$F$34,5,FALSE) -> 0 | L9: =VLOOKUP($A9,'722講義室'!$G$2:$I$34,3,FALSE) -> 0 | M9: =VLOOKUP($D9,'722講義室'!$B$2:$J$34,9,FALSE) -> 0 | N9: =TIME(0, INT($H9/100), MOD($H9,100)) -> 0 | O9: {=_xlfn.LET( _xlpm.t, TIME(0, INT($H9/100), MOD($H9,100)), _xlfn.IFS( AND(_xlpm.t>=TIME(0,7,1), _xlpm.t<=TIME(0,8,19)), 1, AND(_xlpm.t>=TIME(0,6,1), _xlpm.t<=TIME(0,7,0)), 0.8, AND(_xlpm.t>=TIME(0,8,20), _xlpm.t<=TIME(0,8,59)), 0.8, AND(_xlpm.t>=TIME(0,5,1), _xlpm.t<=TIME(0,6,0)), 0.5, AND(_xlpm.t>=TIME(0,9,0), _xlpm.t<=TIME(0,9,59)), 0.5, TRUE, 0.3 ) )} -> 0.3 | P9: =VALUE(LEFT(I9,1)) -> 0 | Q9: =VALUE(LEFT(J9,1)) -> 0 | R9: =VALUE(LEFT(K9,1)) -> 0 | S9: =VALUE(LEFT(L9,1)) -> 0 | T9: =VALUE(LEFT(M9,1)) -> 0
A10: 24G1126 | B10: 三島 遙玖 | C10: ハッカソン２ | D10: 14 | E10: 35 | F10: 722講義室 | G10: =SUM($P10:$T10)*$O10 -> 0 | H10: =VLOOKUP($D10,'722講義室'!$B$2:$F$34,2,FALSE) -> 0 | I10: =VLOOKUP($D10,'722講義室'!$B$2:$F$34,3,FALSE) -> 0 | J10: =VLOOKUP($D10,'722講義室'!$B$2:$F$34,4,FALSE) -> 0 | K10: =VLOOKUP($D10,'722講義室'!$B$2:$F$34,5,FALSE) -> 0 | L10: =VLOOKUP($A10,'722講義室'!$G$2:$I$34,3,FALSE) -> 0 | M10: =VLOOKUP($D10,'722講義室'!$B$2:$J$34,9,FALSE) -> 0 | N10: =TIME(0, INT($H10/100), MOD($H10,100)) -> 0 | O10: {=_xlfn.LET( _xlpm.t, TIME(0, INT($H10/100), MOD($H10,100)), _xlfn.IFS( AND(_xlpm.t>=TIME(0,7,1), _xlpm.t<=TIME(0,8,19)), 1, AND(_xlpm.t>=TIME(0,6,1), _xlpm.t<=TIME(0,7,0)), 0.8, AND(_xlpm.t>=TIME(0,8,20), _xlpm.t<=TIME(0,8,59)), 0.8, AND(_xlpm.t>=TIME(0,5,1), _xlpm.t<=TIME(0,6,0)), 0.5, AND(_xlpm.t>=TIME(0,9,0), _xlpm.t<=TIME(0,9,59)), 0.5, TRUE, 0.3 ) )} -> 0.3 | P10: =VALUE(LEFT(I10,1)) -> 0 | Q10: =VALUE(LEFT(J10,1)) -> 0 | R10: =VALUE(LEFT(K10,1)) -> 0 | S10: =VALUE(LEFT(L10,1)) -> 0 | T10: =VALUE(LEFT(M10,1)) -> 0
A11: 24G1035 | B11: 尾添 遼太 | C11: ハッカソン２ | D11: 32 | E11: 30 | F11: 722講義室 | G11: =SUM($P11:$T11)*$O11 -> 0 | H11: =VLOOKUP($D11,'722講義室'!$B$2:$F$34,2,FALSE) -> 0 | I11: =VLOOKUP($D11,'722講義室'!$B$2:$F$34,3,FALSE) -> 0 | J11: =VLOOKUP($D11,'722講義室'!$B$2:$F$34,4,FALSE) -> 0 | K11: =VLOOKUP($D11,'722講義室'!$B$2:$F$34,5,FALSE) -> 0 | L11: =VLOOKUP($A11,'722講義室'!$G$2:$I$34,3,FALSE) -> 0 | M11: =VLOOKUP($D11,'722講義室'!$B$2:$J$34,9,FALSE) -> 0 | N11: =TIME(0, INT($H11/100), MOD($H11,100)) -> 0 | O11: {=_xlfn.LET( _xlpm.t, TIME(0, INT($H11/100), MOD($H11,100)), _xlfn.IFS( AND(_xlpm.t>=TIME(0,7,1), _xlpm.t<=TIME(0,8,19)), 1, AND(_xlpm.t>=TIME(0,6,1), _xlpm.t<=TIME(0,7,0)), 0.8, AND(_xlpm.t>=TIME(0,8,20), _xlpm.t<=TIME(0,8,59)), 0.8, AND(_xlpm.t>=TIME(0,5,1), _xlpm.t<=TIME(0,6,0)), 0.5, AND(_xlpm.t>=TIME(0,9,0), _xlpm.t<=TIME(0,9,59)), 0.5, TRUE, 0.3 ) )} -> 0.3 | P11: =VALUE(LEFT(I11,1)) -> 0 | Q11: =VALUE(LEFT(J11,1)) -> 0 | R11: =VALUE(LEFT(K11,1)) -> 0 | S11: =VALUE(LEFT(L11,1)) -> 0 | T11: =VALUE(LEFT(M11,1)) -> 0
A12: 24G1056 | B12: 慶田 優 | C12: ハッカソン２ | D12: 32 | E12: 30 | F12: 722講義室 | G12: =SUM($P12:$T12)*$O12 -> 0 | H12: =VLOOKUP($D12,'722講義室'!$B$2:$F$34,2,FALSE) -> 0 | I12: =VLOOKUP($D12,'722講義室'!$B$2:$F$34,3,FALSE) -> 0 | J12: =VLOOKUP($D12,'722講義室'!$B$2:$F$34,4,FALSE) -> 0 | K12: =VLOOKUP($D12,'722講義室'!$B$2:$F$34,5,FALSE) -> 0 | L12: =VLOOKUP($A12,'722講義室'!$G$2:$I$34,3,FALSE) -> 0 | M12: =VLOOKUP($D12,'722講義室'!$B$2:$J$34,9,FALSE) -> 0 | N12: =TIME(0, INT($H12/100), MOD($H12,100)) -> 0 | O12: {=_xlfn.LET( _xlpm.t, TIME(0, INT($H12/100), MOD($H12,100)), _xlfn.IFS( AND(_xlpm.t>=TIME(0,7,1), _xlpm.t<=TIME(0,8,19)), 1, AND(_xlpm.t>=TIME(0,6,1), _xlpm.t<=TIME(0,7,0)), 0.8, AND(_xlpm.t>=TIME(0,8,20), _xlpm.t<=TIME(0,8,59)), 0.8, AND(_xlpm.t>=TIME(0,5,1), _xlpm.t<=TIME(0,6,0)), 0.5, AND(_xlpm.t>=TIME(0,9,0), _xlpm.t<=TIME(0,9,59)), 0.5, TRUE, 0.3 ) )} -> 0.3 | P12: =VALUE(LEFT(I12,1)) -> 0 | Q12: =VALUE(LEFT(J12,1)) -> 0 | R12: =VALUE(LEFT(K12,1)) -> 0 | S12: =VALUE(LEFT(L12,1)) -> 0 | T12: =VALUE(LEFT(M12,1)) -> 0
A13: 24G1101 | B13: 飛田 啓斗 | C13: ハッカソン２ | D13: 32 | E13: 30 | F13: 722講義室 | G13: =SUM($P13:$T13)*$O13 -> 0 | H13: =VLOOKUP($D13,'722講義室'!$B$2:$F$34,2,FALSE) -> 0 | I13: =VLOOKUP($D13,'722講義室'!$B$2:$F$34,3,FALSE) -> 0 | J13: =VLOOKUP($D13,'722講義室'!$B$2:$F$34,4,FALSE) -> 0 | K13: =VLOOKUP($D13,'722講義室'!$B$2:$F$34,5,FALSE) -> 0 | L13: =VLOOKUP($A13,'722講義室'!$G$2:$I$34,3,FALSE) -> 0 | M13: =VLOOKUP($D13,'722講義室'!$B$2:$J$34,9,FALSE) -> 0 | N13: =TIME(0, INT($H13/100), MOD($H13,100)) -> 0 | O13: {=_xlfn.LET( _xlpm.t, TIME(0, INT($H13/100), MOD($H13,100)), _xlfn.IFS( AND(_xlpm.t>=TIME(0,7,1), _xlpm.t<=TIME(0,8,19)), 1, AND(_xlpm.t>=TIME(0,6,1), _xlpm.t<=TIME(0,7,0)), 0.8, AND(_xlpm.t>=TIME(0,8,20), _xlpm.t<=TIME(0,8,59)), 0.8, AND(_xlpm.t>=TIME(0,5,1), _xlpm.t<=TIME(0,6,0)), 0.5, AND(_xlpm.t>=TIME(0,9,0), _xlpm.t<=TIME(0,9,59)), 0.5, TRUE, 0.3 ) )} -> 0.3 | P13: =VALUE(LEFT(I13,1)) -> 0 | Q13: =VALUE(LEFT(J13,1)) -> 0 | R13: =VALUE(LEFT(K13,1)) -> 0 | S13: =VALUE(LEFT(L13,1)) -> 0 | T13: =VALUE(LEFT(M13,1)) -> 0
... A34: 24G1125 | B34: 三芝 空音 | C34: ハッカソン２ | D34: 26 | E34: 3 | F34: 722講義室 | G34: =SUM($P34:$T34)*$O34 -> 0 | H34: =VLOOKUP($D34,'722講義室'!$B$2:$F$34,2,FALSE) -> 0 | I34: =VLOOKUP($D34,'722講義室'!$B$2:$F$34,3,FALSE) -> 0 | J34: =VLOOKUP($D34,'722講義室'!$B$2:$F$34,4,FALSE) -> 0 | K34: =VLOOKUP($D34,'722講義室'!$B$2:$F$34,5,FALSE) -> 0 | L34: =VLOOKUP($A34,'722講義室'!$G$2:$I$34,3,FALSE) -> 0 | M34: =VLOOKUP($D34,'722講義室'!$B$2:$J$34,9,FALSE) -> 0 | N34: =TIME(0, INT($H34/100), MOD($H34,100)) -> 0 | O34: {=_xlfn.LET( _xlpm.t, TIME(0, INT($H34/100), MOD($H34,100)), _xlfn.IFS( AND(_xlpm.t>=TIME(0,7,1), _xlpm.t<=TIME(0,8,19)), 1, AND(_xlpm.t>=TIME(0,6,1), _xlpm.t<=TIME(0,7,0)), 0.8, AND(_xlpm.t>=TIME(0,8,20), _xlpm.t<=TIME(0,8,59)), 0.8, AND(_xlpm.t>=TIME(0,5,1), _xlpm.t<=TIME(0,6,0)), 0.5, AND(_xlpm.t>=TIME(0,9,0), _xlpm.t<=TIME(0,9,59)), 0.5, TRUE, 0.3 ) )} -> 0.3 | P34: =VALUE(LEFT(I34,1)) -> 0 | Q34: =VALUE(LEFT(J34,1)) -> 0 | R34: =VALUE(LEFT(K34,1)) -> 0 | S34: =VALUE(LEFT(L34,1)) -> 0 | T34: =VALUE(LEFT(M34,1)) -> 0
A35: 24G1012 | B35: 石坂 琢磨 | C35: ハッカソン２ | D35: 10 | E35: 40 | F35: 731講義室 | G35: =SUM($P35:$T35)*$O35 -> 0 | H35: =VLOOKUP($D35,'731講義室'!$B$2:$F$34,2,FALSE) -> 0 | I35: =VLOOKUP($D35,'731講義室'!$B$2:$F$34,3,FALSE) -> 0 | J35: =VLOOKUP($D35,'731講義室'!$B$2:$F$34,4,FALSE) -> 0 | K35: =VLOOKUP($D35,'731講義室'!$B$2:$F$34,5,FALSE) -> 0 | L35: =VLOOKUP($A35,'731講義室'!$G$2:$I$34,3,FALSE) -> 0 | M35: =VLOOKUP($D35,'731講義室'!$B$2:$J$34,9,FALSE) -> 0 | N35: =TIME(0, INT($H35/100), MOD($H35,100)) -> 0 | O35: {=_xlfn.LET( _xlpm.t, TIME(0, INT($H35/100), MOD($H35,100)), _xlfn.IFS( AND(_xlpm.t>=TIME(0,7,1), _xlpm.t<=TIME(0,8,19)), 1, AND(_xlpm.t>=TIME(0,6,1), _xlpm.t<=TIME(0,7,0)), 0.8, AND(_xlpm.t>=TIME(0,8,20), _xlpm.t<=TIME(0,8,59)), 0.8, AND(_xlpm.t>=TIME(0,5,1), _xlpm.t<=TIME(0,6,0)), 0.5, AND(_xlpm.t>=TIME(0,9,0), _xlpm.t<=TIME(0,9,59)), 0.5, TRUE, 0.3 ) )} -> 0.3 | P35: =VALUE(LEFT(I35,1)) -> 0 | Q35: =VALUE(LEFT(J35,1)) -> 0 | R35: =VALUE(LEFT(K35,1)) -> 0 | S35: =VALUE(LEFT(L35,1)) -> 0 | T35: =VALUE(LEFT(M35,1)) -> 0
A36: 24G1032 | B36: 荻野 泰地 | C36: ハッカソン２ | D36: 10 | E36: 40 | F36: 731講義室 | G36: =SUM($P36:$T36)*$O36 -> 0 | H36: =VLOOKUP($D36,'731講義室'!$B$2:$F$34,2,FALSE) -> 0 | I36: =VLOOKUP($D36,'731講義室'!$B$2:$F$34,3,FALSE) -> 0 | J36: =VLOOKUP($D36,'731講義室'!$B$2:$F$34,4,FALSE) -> 0 | K36: =VLOOKUP($D36,'731講義室'!$B$2:$F$34,5,FALSE) -> 0 | L36: =VLOOKUP($A36,'731講義室'!$G$2:$I$34,3,FALSE) -> 0 | M36: =VLOOKUP($D36,'731講義室'!$B$2:$J$34,9,FALSE) -> 0 | N36: =TIME(0, INT($H36/100), MOD($H36,100)) -> 0 | O36: {=_xlfn.LET( _xlpm.t, TIME(0, INT($H36/100), MOD($H36,100)), _xlfn.IFS( AND(_xlpm.t>=TIME(0,7,1), _xlpm.t<=TIME(0,8,19)), 1, AND(_xlpm.t>=TIME(0,6,1), _xlpm.t<=TIME(0,7,0)), 0.8, AND(_xlpm.t>=TIME(0,8,20), _xlpm.t<=TIME(0,8,59)), 0.8, AND(_xlpm.t>=TIME(0,5,1), _xlpm.t<=TIME(0,6,0)), 0.5, AND(_xlpm.t>=TIME(0,9,0), _xlpm.t<=TIME(0,9,59)), 0.5, TRUE, 0.3 ) )} -> 0.3 | P36: =VALUE(LEFT(I36,1)) -> 0 | Q36: =VALUE(LEFT(J36,1)) -> 0 | R36: =VALUE(LEFT(K36,1)) -> 0 | S36: =VALUE(LEFT(L36,1)) -> 0 | T36: =VALUE(LEFT(M36,1)) -> 0
A37: 24G1146 | B37: 渡邉 那音 | C37: ハッカソン２ | D37: 10 | E37: 40 | F37: 731講義室 | G37: =SUM($P37:$T37)*$O37 -> 0 | H37: =VLOOKUP($D37,'731講義室'!$B$2:$F$34,2,FALSE) -> 0 | I37: =VLOOKUP($D37,'731講義室'!$B$2:$F$34,3,FALSE) -> 0 | J37: =VLOOKUP($D37,'731講義室'!$B$2:$F$34,4,FALSE) -> 0 | K37: =VLOOKUP($D37,'731講義室'!$B$2:$F$34,5,FALSE) -> 0 | L37: =VLOOKUP($A37,'731講義室'!$G$2:$I$34,3,FALSE) -> 0 | M37: =VLOOKUP($D37,'731講義室'!$B$2:$J$34,9,FALSE) -> 0 | N37: =TIME(0, INT($H37/100), MOD($H37,100)) -> 0 | O37: {=_xlfn.LET( _xlpm.t, TIME(0, INT($H37/100), MOD($H37,100)), _xlfn.IFS( AND(_xlpm.t>=TIME(0,7,1), _xlpm.t<=TIME(0,8,19)), 1, AND(_xlpm.t>=TIME(0,6,1), _xlpm.t<=TIME(0,7,0)), 0.8, AND(_xlpm.t>=TIME(0,8,20), _xlpm.t<=TIME(0,8,59)), 0.8, AND(_xlpm.t>=TIME(0,5,1), _xlpm.t<=TIME(0,6,0)), 0.5, AND(_xlpm.t>=TIME(0,9,0), _xlpm.t<=TIME(0,9,59)), 0.5, TRUE, 0.3 ) )} -> 0.3 | P37: =VALUE(LEFT(I37,1)) -> 0 | Q37: =VALUE(LEFT(J37,1)) -> 0 | R37: =VALUE(LEFT(K37,1)) -> 0 | S37: =VALUE(LEFT(L37,1)) -> 0 | T37: =VALUE(LEFT(M37,1)) -> 0
A38: 24G1002 | B38: 秋葉 聖哉 | C38: ハッカソン２ | D38: 37 | E38: 39 | F38: 731講義室 | G38: =SUM($P38:$T38)*$O38 -> 0 | H38: =VLOOKUP($D38,'731講義室'!$B$2:$F$34,2,FALSE) -> 0 | I38: =VLOOKUP($D38,'731講義室'!$B$2:$F$34,3,FALSE) -> 0 | J38: =VLOOKUP($D38,'731講義室'!$B$2:$F$34,4,FALSE) -> 0 | K38: =VLOOKUP($D38,'731講義室'!$B$2:$F$34,5,FALSE) -> 0 | L38: =VLOOKUP($A38,'731講義室'!$G$2:$I$34,3,FALSE) -> 0 | M38: =VLOOKUP($D38,'731講義室'!$B$2:$J$34,9,FALSE) -> 0 | N38: =TIME(0, INT($H38/100), MOD($H38,100)) -> 0 | O38: {=_xlfn.LET( _xlpm.t, TIME(0, INT($H38/100), MOD($H38,100)), _xlfn.IFS( AND(_xlpm.t>=TIME(0,7,1), _xlpm.t<=TIME(0,8,19)), 1, AND(_xlpm.t>=TIME(0,6,1), _xlpm.t<=TIME(0,7,0)), 0.8, AND(_xlpm.t>=TIME(0,8,20), _xlpm.t<=TIME(0,8,59)), 0.8, AND(_xlpm.t>=TIME(0,5,1), _xlpm.t<=TIME(0,6,0)), 0.5, AND(_xlpm.t>=TIME(0,9,0), _xlpm.t<=TIME(0,9,59)), 0.5, TRUE, 0.3 ) )} -> 0.3 | P38: =VALUE(LEFT(I38,1)) -> 0 | Q38: =VALUE(LEFT(J38,1)) -> 0 | R38: =VALUE(LEFT(K38,1)) -> 0 | S38: =VALUE(LEFT(L38,1)) -> 0 | T38: =VALUE(LEFT(M38,1)) -> 0
A39: 24G1109 | B39: 林田 裕太朗 | C39: ハッカソン２ | D39: 37 | E39: 39 | F39: 731講義室 | G39: =SUM($P39:$T39)*$O39 -> 0 | H39: =VLOOKUP($D39,'731講義室'!$B$2:$F$34,2,FALSE) -> 0 | I39: =VLOOKUP($D39,'731講義室'!$B$2:$F$34,3,FALSE) -> 0 | J39: =VLOOKUP($D39,'731講義室'!$B$2:$F$34,4,FALSE) -> 0 | K39: =VLOOKUP($D39,'731講義室'!$B$2:$F$34,5,FALSE) -> 0 | L39: =VLOOKUP($A39,'731講義室'!$G$2:$I$34,3,FALSE) -> 0 | M39: =VLOOKUP($D39,'731講義室'!$B$2:$J$34,9,FALSE) -> 0 | N39: =TIME(0, INT($H39/100), MOD($H39,100)) -> 0 | O39: {=_xlfn.LET( _xlpm.t, TIME(0, INT($H39/100), MOD($H39,100)), _xlfn.IFS( AND(_xlpm.t>=TIME(0,7,1), _xlpm.t<=TIME(0,8,19)), 1, AND(_xlpm.t>=TIME(0,6,1), _xlpm.t<=TIME(0,7,0)), 0.8, AND(_xlpm.t>=TIME(0,8,20), _xlpm.t<=TIME(0,8,59)), 0.8, AND(_xlpm.t>=TIME(0,5,1), _xlpm.t<=TIME(0,6,0)), 0.5, AND(_xlpm.t>=TIME(0,9,0), _xlpm.t<=TIME(0,9,59)), 0.5, TRUE, 0.3 ) )} -> 0.3 | P39: =VALUE(LEFT(I39,1)) -> 0 | Q39: =VALUE(LEFT(J39,1)) -> 0 | R39: =VALUE(LEFT(K39,1)) -> 0 | S39: =VALUE(LEFT(L39,1)) -> 0 | T39: =VALUE(LEFT(M39,1)) -> 0
A40: 24G1124 | B40: 三木 俊英 | C40: ハッカソン２ | D40: 37 | E40: 39 | F40: 731講義室 | G40: =SUM($P40:$T40)*$O40 -> 0 | H40: =VLOOKUP($D40,'731講義室'!$B$2:$F$34,2,FALSE) -> 0 | I40: =VLOOKUP($D40,'731講義室'!$B$2:$F$34,3,FALSE) -> 0 | J40: =VLOOKUP($D40,'731講義室'!$B$2:$F$34,4,FALSE) -> 0 | K40: =VLOOKUP($D40,'731講義室'!$B$2:$F$34,5,FALSE) -> 0 | L40: =VLOOKUP($A40,'731講義室'!$G$2:$I$34,3,FALSE) -> 0 | M40: =VLOOKUP($D40,'731講義室'!$B$2:$J$34,9,FALSE) -> 0 | N40: =TIME(0, INT($H40/100), MOD($H40,100)) -> 0 | O40: {=_xlfn.LET( _xlpm.t, TIME(0, INT($H40/100), MOD($H40,100)), _xlfn.IFS( AND(_xlpm.t>=TIME(0,7,1), _xlpm.t<=TIME(0,8,19)), 1, AND(_xlpm.t>=TIME(0,6,1), _xlpm.t<=TIME(0,7,0)), 0.8, AND(_xlpm.t>=TIME(0,8,20), _xlpm.t<=TIME(0,8,59)), 0.8, AND(_xlpm.t>=TIME(0,5,1), _xlpm.t<=TIME(0,6,0)), 0.5, AND(_xlpm.t>=TIME(0,9,0), _xlpm.t<=TIME(0,9,59)), 0.5, TRUE, 0.3 ) )} -> 0.3 | P40: =VALUE(LEFT(I40,1)) -> 0 | Q40: =VALUE(LEFT(J40,1)) -> 0 | R40: =VALUE(LEFT(K40,1)) -> 0 | S40: =VALUE(LEFT(L40,1)) -> 0 | T40: =VALUE(LEFT(M40,1)) -> 0
A41: 24G1016 | B41: 伊藤 脩 | C41: ハッカソン２ | D41: 33 | E41: 34 | F41: 731講義室 | G41: =SUM($P41:$T41)*$O41 -> 0 | H41: =VLOOKUP($D41,'731講義室'!$B$2:$F$34,2,FALSE) -> 0 | I41: =VLOOKUP($D41,'731講義室'!$B$2:$F$34,3,FALSE) -> 0 | J41: =VLOOKUP($D41,'731講義室'!$B$2:$F$34,4,FALSE) -> 0 | K41: =VLOOKUP($D41,'731講義室'!$B$2:$F$34,5,FALSE) -> 0 | L41: =VLOOKUP($A41,'731講義室'!$G$2:$I$34,3,FALSE) -> 0 | M41: =VLOOKUP($D41,'731講義室'!$B$2:$J$34,9,FALSE) -> 0 | N41: =TIME(0, INT($H41/100), MOD($H41,100)) -> 0 | O41: {=_xlfn.LET( _xlpm.t, TIME(0, INT($H41/100), MOD($H41,100)), _xlfn.IFS( AND(_xlpm.t>=TIME(0,7,1), _xlpm.t<=TIME(0,8,19)), 1, AND(_xlpm.t>=TIME(0,6,1), _xlpm.t<=TIME(0,7,0)), 0.8, AND(_xlpm.t>=TIME(0,8,20), _xlpm.t<=TIME(0,8,59)), 0.8, AND(_xlpm.t>=TIME(0,5,1), _xlpm.t<=TIME(0,6,0)), 0.5, AND(_xlpm.t>=TIME(0,9,0), _xlpm.t<=TIME(0,9,59)), 0.5, TRUE, 0.3 ) )} -> 0.3 | P41: =VALUE(LEFT(I41,1)) -> 0 | Q41: =VALUE(LEFT(J41,1)) -> 0 | R41: =VALUE(LEFT(K41,1)) -> 0 | S41: =VALUE(LEFT(L41,1)) -> 0 | T41: =VALUE(LEFT(M41,1)) -> 0
A42: 24G1031 | B42: 小川 泰生 | C42: ハッカソン２ | D42: 33 | E42: 34 | F42: 731講義室 | G42: =SUM($P42:$T42)*$O42 -> 0 | H42: =VLOOKUP($D42,'731講義室'!$B$2:$F$34,2,FALSE) -> 0 | I42: =VLOOKUP($D42,'731講義室'!$B$2:$F$34,3,FALSE) -> 0 | J42: =VLOOKUP($D42,'731講義室'!$B$2:$F$34,4,FALSE) -> 0 | K42: =VLOOKUP($D42,'731講義室'!$B$2:$F$34,5,FALSE) -> 0 | L42: =VLOOKUP($A42,'731講義室'!$G$2:$I$34,3,FALSE) -> 0 | M42: =VLOOKUP($D42,'731講義室'!$B$2:$J$34,9,FALSE) -> 0 | N42: =TIME(0, INT($H42/100), MOD($H42,100)) -> 0 | O42: {=_xlfn.LET( _xlpm.t, TIME(0, INT($H42/100), MOD($H42,100)), _xlfn.IFS( AND(_xlpm.t>=TIME(0,7,1), _xlpm.t<=TIME(0,8,19)), 1, AND(_xlpm.t>=TIME(0,6,1), _xlpm.t<=TIME(0,7,0)), 0.8, AND(_xlpm.t>=TIME(0,8,20), _xlpm.t<=TIME(0,8,59)), 0.8, AND(_xlpm.t>=TIME(0,5,1), _xlpm.t<=TIME(0,6,0)), 0.5, AND(_xlpm.t>=TIME(0,9,0), _xlpm.t<=TIME(0,9,59)), 0.5, TRUE, 0.3 ) )} -> 0.3 | P42: =VALUE(LEFT(I42,1)) -> 0 | Q42: =VALUE(LEFT(J42,1)) -> 0 | R42: =VALUE(LEFT(K42,1)) -> 0 | S42: =VALUE(LEFT(L42,1)) -> 0 | T42: =VALUE(LEFT(M42,1)) -> 0
A43: 24G1083 | B43: 清宮 俊 | C43: ハッカソン２ | D43: 33 | E43: 34 | F43: 731講義室 | G43: =SUM($P43:$T43)*$O43 -> 0 | H43: =VLOOKUP($D43,'731講義室'!$B$2:$F$34,2,FALSE) -> 0 | I43: =VLOOKUP($D43,'731講義室'!$B$2:$F$34,3,FALSE) -> 0 | J43: =VLOOKUP($D43,'731講義室'!$B$2:$F$34,4,FALSE) -> 0 | K43: =VLOOKUP($D43,'731講義室'!$B$2:$F$34,5,FALSE) -> 0 | L43: =VLOOKUP($A43,'731講義室'!$G$2:$I$34,3,FALSE) -> 0 | M43: =VLOOKUP($D43,'731講義室'!$B$2:$J$34,9,FALSE) -> 0 | N43: =TIME(0, INT($H43/100), MOD($H43,100)) -> 0 | O43: {=_xlfn.LET( _xlpm.t, TIME(0, INT($H43/100), MOD($H43,100)), _xlfn.IFS( AND(_xlpm.t>=TIME(0,7,1), _xlpm.t<=TIME(0,8,19)), 1, AND(_xlpm.t>=TIME(0,6,1), _xlpm.t<=TIME(0,7,0)), 0.8, AND(_xlpm.t>=TIME(0,8,20), _xlpm.t<=TIME(0,8,59)), 0.8, AND(_xlpm.t>=TIME(0,5,1), _xlpm.t<=TIME(0,6,0)), 0.5, AND(_xlpm.t>=TIME(0,9,0), _xlpm.t<=TIME(0,9,59)), 0.5, TRUE, 0.3 ) )} -> 0.3 | P43: =VALUE(LEFT(I43,1)) -> 0 | Q43: =VALUE(LEFT(J43,1)) -> 0 | R43: =VALUE(LEFT(K43,1)) -> 0 | S43: =VALUE(LEFT(L43,1)) -> 0 | T43: =VALUE(LEFT(M43,1)) -> 0
A44: 24G1005 | B44: 淺沼 龍太 | C44: ハッカソン２ | D44: 42 | E44: 31 | F44: 731講義室 | G44: =SUM($P44:$T44)*$O44 -> 0 | H44: =VLOOKUP($D44,'731講義室'!$B$2:$F$34,2,FALSE) -> 0 | I44: =VLOOKUP($D44,'731講義室'!$B$2:$F$34,3,FALSE) -> 0 | J44: =VLOOKUP($D44,'731講義室'!$B$2:$F$34,4,FALSE) -> 0 | K44: =VLOOKUP($D44,'731講義室'!$B$2:$F$34,5,FALSE) -> 0 | L44: =VLOOKUP($A44,'731講義室'!$G$2:$I$34,3,FALSE) -> 0 | M44: =VLOOKUP($D44,'731講義室'!$B$2:$J$34,9,FALSE) -> 0 | N44: =TIME(0, INT($H44/100), MOD($H44,100)) -> 0 | O44: {=_xlfn.LET( _xlpm.t, TIME(0, INT($H44/100), MOD($H44,100)), _xlfn.IFS( AND(_xlpm.t>=TIME(0,7,1), _xlpm.t<=TIME(0,8,19)), 1, AND(_xlpm.t>=TIME(0,6,1), _xlpm.t<=TIME(0,7,0)), 0.8, AND(_xlpm.t>=TIME(0,8,20), _xlpm.t<=TIME(0,8,59)), 0.8, AND(_xlpm.t>=TIME(0,5,1), _xlpm.t<=TIME(0,6,0)), 0.5, AND(_xlpm.t>=TIME(0,9,0), _xlpm.t<=TIME(0,9,59)), 0.5, TRUE, 0.3 ) )} -> 0.3 | P44: =VALUE(LEFT(I44,1)) -> 0 | Q44: =VALUE(LEFT(J44,1)) -> 0 | R44: =VALUE(LEFT(K44,1)) -> 0 | S44: =VALUE(LEFT(L44,1)) -> 0 | T44: =VALUE(LEFT(M44,1)) -> 0
A45: 24G1078 | B45: 鈴木 琉 | C45: ハッカソン２ | D45: 42 | E45: 31 | F45: 731講義室 | G45: =SUM($P45:$T45)*$O45 -> 0 | H45: =VLOOKUP($D45,'731講義室'!$B$2:$F$34,2,FALSE) -> 0 | I45: =VLOOKUP($D45,'731講義室'!$B$2:$F$34,3,FALSE) -> 0 | J45: =VLOOKUP($D45,'731講義室'!$B$2:$F$34,4,FALSE) -> 0 | K45: =VLOOKUP($D45,'731講義室'!$B$2:$F$34,5,FALSE) -> 0 | L45: =VLOOKUP($A45,'731講義室'!$G$2:$I$34,3,FALSE) -> 0 | M45: =VLOOKUP($D45,'731講義室'!$B$2:$J$34,9,FALSE) -> 0 | N45: =TIME(0, INT($H45/100), MOD($H45,100)) -> 0 | O45: {=_xlfn.LET( _xlpm.t, TIME(0, INT($H45/100), MOD($H45,100)), _xlfn.IFS( AND(_xlpm.t>=TIME(0,7,1), _xlpm.t<=TIME(0,8,19)), 1, AND(_xlpm.t>=TIME(0,6,1), _xlpm.t<=TIME(0,7,0)), 0.8, AND(_xlpm.t>=TIME(0,8,20), _xlpm.t<=TIME(0,8,59)), 0.8, AND(_xlpm.t>=TIME(0,5,1), _xlpm.t<=TIME(0,6,0)), 0.5, AND(_xlpm.t>=TIME(0,9,0), _xlpm.t<=TIME(0,9,59)), 0.5, TRUE, 0.3 ) )} -> 0.3 | P45: =VALUE(LEFT(I45,1)) -> 0 | Q45: =VALUE(LEFT(J45,1)) -> 0 | R45: =VALUE(LEFT(K45,1)) -> 0 | S45: =VALUE(LEFT(L45,1)) -> 0 | T45: =VALUE(LEFT(M45,1)) -> 0
A46: 24G1111 | B46: 原 颯登 | C46: ハッカソン２ | D46: 42 | E46: 31 | F46: 731講義室 | G46: =SUM($P46:$T46)*$O46 -> 0 | H46: =VLOOKUP($D46,'731講義室'!$B$2:$F$34,2,FALSE) -> 0 | I46: =VLOOKUP($D46,'731講義室'!$B$2:$F$34,3,FALSE) -> 0 | J46: =VLOOKUP($D46,'731講義室'!$B$2:$F$34,4,FALSE) -> 0 | K46: =VLOOKUP($D46,'731講義室'!$B$2:$F$34,5,FALSE) -> 0 | L46: =VLOOKUP($A46,'731講義室'!$G$2:$I$34,3,FALSE) -> 0 | M46: =VLOOKUP($D46,'731講義室'!$B$2:$J$34,9,FALSE) -> 0 | N46: =TIME(0, INT($H46/100), MOD($H46,100)) -> 0 | O46: {=_xlfn.LET( _xlpm.t, TIME(0, INT($H46/100), MOD($H46,100)), _xlfn.IFS( AND(_xlpm.t>=TIME(0,7,1), _xlpm.t<=TIME(0,8,19)), 1, AND(_xlpm.t>=TIME(0,6,1), _xlpm.t<=TIME(0,7,0)), 0.8, AND(_xlpm.t>=TIME(0,8,20), _xlpm.t<=TIME(0,8,59)), 0.8, AND(_xlpm.t>=TIME(0,5,1), _xlpm.t<=TIME(0,6,0)), 0.5, AND(_xlpm.t>=TIME(0,9,0), _xlpm.t<=TIME(0,9,59)), 0.5, TRUE, 0.3 ) )} -> 0.3 | P46: =VALUE(LEFT(I46,1)) -> 0 | Q46: =VALUE(LEFT(J46,1)) -> 0 | R46: =VALUE(LEFT(K46,1)) -> 0 | S46: =VALUE(LEFT(L46,1)) -> 0 | T46: =VALUE(LEFT(M46,1)) -> 0
... A67: 24G1122 | B67: 細澤 悠真 | C67: ハッカソン２ | D67: 4 | E67: 2 | F67: 731講義室 | G67: =SUM($P67:$T67)*$O67 -> 0 | H67: =VLOOKUP($D67,'731講義室'!$B$2:$F$34,2,FALSE) -> 0 | I67: =VLOOKUP($D67,'731講義室'!$B$2:$F$34,3,FALSE) -> 0 | J67: =VLOOKUP($D67,'731講義室'!$B$2:$F$34,4,FALSE) -> 0 | K67: =VLOOKUP($D67,'731講義室'!$B$2:$F$34,5,FALSE) -> 0 | L67: =VLOOKUP($A67,'731講義室'!$G$2:$I$34,3,FALSE) -> 0 | M67: =VLOOKUP($D67,'731講義室'!$B$2:$J$34,9,FALSE) -> 0 | N67: =TIME(0, INT($H67/100), MOD($H67,100)) -> 0 | O67: {=_xlfn.LET( _xlpm.t, TIME(0, INT($H67/100), MOD($H67,100)), _xlfn.IFS( AND(_xlpm.t>=TIME(0,7,1), _xlpm.t<=TIME(0,8,19)), 1, AND(_xlpm.t>=TIME(0,6,1), _xlpm.t<=TIME(0,7,0)), 0.8, AND(_xlpm.t>=TIME(0,8,20), _xlpm.t<=TIME(0,8,59)), 0.8, AND(_xlpm.t>=TIME(0,5,1), _xlpm.t<=TIME(0,6,0)), 0.5, AND(_xlpm.t>=TIME(0,9,0), _xlpm.t<=TIME(0,9,59)), 0.5, TRUE, 0.3 ) )} -> 0.3 | P67: =VALUE(LEFT(I67,1)) -> 0 | Q67: =VALUE(LEFT(J67,1)) -> 0 | R67: =VALUE(LEFT(K67,1)) -> 0 | S67: =VALUE(LEFT(L67,1)) -> 0 | T67: =VALUE(LEFT(M67,1)) -> 0
A68: 24G1105 | B68: 長妻 冬威 | C68: ハッカソン２ | D68: 28 | E68: 42 | F68: 732講義室 | G68: =SUM($P68:$T68)*$O68 -> 0 | H68: =VLOOKUP($D68,'732講義室'!$B$2:$F$34,2,FALSE) -> 0 | I68: =VLOOKUP($D68,'732講義室'!$B$2:$F$34,3,FALSE) -> 0 | J68: =VLOOKUP($D68,'732講義室'!$B$2:$F$34,4,FALSE) -> 0 | K68: =VLOOKUP($D68,'732講義室'!$B$2:$F$34,5,FALSE) -> 0 | L68: =VLOOKUP($A68,'732講義室'!$G$2:$I$34,3,FALSE) -> 0 | M68: =VLOOKUP($D68,'732講義室'!$B$2:$J$34,9,FALSE) -> 0 | N68: =TIME(0, INT($H68/100), MOD($H68,100)) -> 0 | O68: {=_xlfn.LET( _xlpm.t, TIME(0, INT($H68/100), MOD($H68,100)), _xlfn.IFS( AND(_xlpm.t>=TIME(0,7,1), _xlpm.t<=TIME(0,8,19)), 1, AND(_xlpm.t>=TIME(0,6,1), _xlpm.t<=TIME(0,7,0)), 0.8, AND(_xlpm.t>=TIME(0,8,20), _xlpm.t<=TIME(0,8,59)), 0.8, AND(_xlpm.t>=TIME(0,5,1), _xlpm.t<=TIME(0,6,0)), 0.5, AND(_xlpm.t>=TIME(0,9,0), _xlpm.t<=TIME(0,9,59)), 0.5, TRUE, 0.3 ) )} -> 0.3 | P68: =VALUE(LEFT(I68,1)) -> 0 | Q68: =VALUE(LEFT(J68,1)) -> 0 | R68: =VALUE(LEFT(K68,1)) -> 0 | S68: =VALUE(LEFT(L68,1)) -> 0 | T68: =VALUE(LEFT(M68,1)) -> 0
A69: 24G1110 | B69: 葉山 颯太 | C69: ハッカソン２ | D69: 28 | E69: 42 | F69: 732講義室 | G69: =SUM($P69:$T69)*$O69 -> 0 | H69: =VLOOKUP($D69,'732講義室'!$B$2:$F$34,2,FALSE) -> 0 | I69: =VLOOKUP($D69,'732講義室'!$B$2:$F$34,3,FALSE) -> 0 | J69: =VLOOKUP($D69,'732講義室'!$B$2:$F$34,4,FALSE) -> 0 | K69: =VLOOKUP($D69,'732講義室'!$B$2:$F$34,5,FALSE) -> 0 | L69: =VLOOKUP($A69,'732講義室'!$G$2:$I$34,3,FALSE) -> 0 | M69: =VLOOKUP($D69,'732講義室'!$B$2:$J$34,9,FALSE) -> 0 | N69: =TIME(0, INT($H69/100), MOD($H69,100)) -> 0 | O69: {=_xlfn.LET( _xlpm.t, TIME(0, INT($H69/100), MOD($H69,100)), _xlfn.IFS( AND(_xlpm.t>=TIME(0,7,1), _xlpm.t<=TIME(0,8,19)), 1, AND(_xlpm.t>=TIME(0,6,1), _xlpm.t<=TIME(0,7,0)), 0.8, AND(_xlpm.t>=TIME(0,8,20), _xlpm.t<=TIME(0,8,59)), 0.8, AND(_xlpm.t>=TIME(0,5,1), _xlpm.t<=TIME(0,6,0)), 0.5, AND(_xlpm.t>=TIME(0,9,0), _xlpm.t<=TIME(0,9,59)), 0.5, TRUE, 0.3 ) )} -> 0.3 | P69: =VALUE(LEFT(I69,1)) -> 0 | Q69: =VALUE(LEFT(J69,1)) -> 0 | R69: =VALUE(LEFT(K69,1)) -> 0 | S69: =VALUE(LEFT(L69,1)) -> 0 | T69: =VALUE(LEFT(M69,1)) -> 0
A70: 24G1127 | B70: 水田 悠斗 | C70: ハッカソン２ | D70: 28 | E70: 42 | F70: 732講義室 | G70: =SUM($P70:$T70)*$O70 -> 0 | H70: =VLOOKUP($D70,'732講義室'!$B$2:$F$34,2,FALSE) -> 0 | I70: =VLOOKUP($D70,'732講義室'!$B$2:$F$34,3,FALSE) -> 0 | J70: =VLOOKUP($D70,'732講義室'!$B$2:$F$34,4,FALSE) -> 0 | K70: =VLOOKUP($D70,'732講義室'!$B$2:$F$34,5,FALSE) -> 0 | L70: =VLOOKUP($A70,'732講義室'!$G$2:$I$34,3,FALSE) -> 0 | M70: =VLOOKUP($D70,'732講義室'!$B$2:$J$34,9,FALSE) -> 0 | N70: =TIME(0, INT($H70/100), MOD($H70,100)) -> 0 | O70: {=_xlfn.LET( _xlpm.t, TIME(0, INT($H70/100), MOD($H70,100)), _xlfn.IFS( AND(_xlpm.t>=TIME(0,7,1), _xlpm.t<=TIME(0,8,19)), 1, AND(_xlpm.t>=TIME(0,6,1), _xlpm.t<=TIME(0,7,0)), 0.8, AND(_xlpm.t>=TIME(0,8,20), _xlpm.t<=TIME(0,8,59)), 0.8, AND(_xlpm.t>=TIME(0,5,1), _xlpm.t<=TIME(0,6,0)), 0.5, AND(_xlpm.t>=TIME(0,9,0), _xlpm.t<=TIME(0,9,59)), 0.5, TRUE, 0.3 ) )} -> 0.3 | P70: =VALUE(LEFT(I70,1)) -> 0 | Q70: =VALUE(LEFT(J70,1)) -> 0 | R70: =VALUE(LEFT(K70,1)) -> 0 | S70: =VALUE(LEFT(L70,1)) -> 0 | T70: =VALUE(LEFT(M70,1)) -> 0
A71: 24G1011 | B71: 石川 敏伸 | C71: ハッカソン２ | D71: 39 | E71: 37 | F71: 732講義室 | G71: =SUM($P71:$T71)*$O71 -> 0 | H71: =VLOOKUP($D71,'732講義室'!$B$2:$F$34,2,FALSE) -> 0 | I71: =VLOOKUP($D71,'732講義室'!$B$2:$F$34,3,FALSE) -> 0 | J71: =VLOOKUP($D71,'732講義室'!$B$2:$F$34,4,FALSE) -> 0 | K71: =VLOOKUP($D71,'732講義室'!$B$2:$F$34,5,FALSE) -> 0 | L71: =VLOOKUP($A71,'732講義室'!$G$2:$I$34,3,FALSE) -> 0 | M71: =VLOOKUP($D71,'732講義室'!$B$2:$J$34,9,FALSE) -> 0 | N71: =TIME(0, INT($H71/100), MOD($H71,100)) -> 0 | O71: {=_xlfn.LET( _xlpm.t, TIME(0, INT($H71/100), MOD($H71,100)), _xlfn.IFS( AND(_xlpm.t>=TIME(0,7,1), _xlpm.t<=TIME(0,8,19)), 1, AND(_xlpm.t>=TIME(0,6,1), _xlpm.t<=TIME(0,7,0)), 0.8, AND(_xlpm.t>=TIME(0,8,20), _xlpm.t<=TIME(0,8,59)), 0.8, AND(_xlpm.t>=TIME(0,5,1), _xlpm.t<=TIME(0,6,0)), 0.5, AND(_xlpm.t>=TIME(0,9,0), _xlpm.t<=TIME(0,9,59)), 0.5, TRUE, 0.3 ) )} -> 0.3 | P71: =VALUE(LEFT(I71,1)) -> 0 | Q71: =VALUE(LEFT(J71,1)) -> 0 | R71: =VALUE(LEFT(K71,1)) -> 0 | S71: =VALUE(LEFT(L71,1)) -> 0 | T71: =VALUE(LEFT(M71,1)) -> 0
A72: 24G1044 | B72: 河井 晴仁 | C72: ハッカソン２ | D72: 39 | E72: 37 | F72: 732講義室 | G72: =SUM($P72:$T72)*$O72 -> 0 | H72: =VLOOKUP($D72,'732講義室'!$B$2:$F$34,2,FALSE) -> 0 | I72: =VLOOKUP($D72,'732講義室'!$B$2:$F$34,3,FALSE) -> 0 | J72: =VLOOKUP($D72,'732講義室'!$B$2:$F$34,4,FALSE) -> 0 | K72: =VLOOKUP($D72,'732講義室'!$B$2:$F$34,5,FALSE) -> 0 | L72: =VLOOKUP($A72,'732講義室'!$G$2:$I$34,3,FALSE) -> 0 | M72: =VLOOKUP($D72,'732講義室'!$B$2:$J$34,9,FALSE) -> 0 | N72: =TIME(0, INT($H72/100), MOD($H72,100)) -> 0 | O72: {=_xlfn.LET( _xlpm.t, TIME(0, INT($H72/100), MOD($H72,100)), _xlfn.IFS( AND(_xlpm.t>=TIME(0,7,1), _xlpm.t<=TIME(0,8,19)), 1, AND(_xlpm.t>=TIME(0,6,1), _xlpm.t<=TIME(0,7,0)), 0.8, AND(_xlpm.t>=TIME(0,8,20), _xlpm.t<=TIME(0,8,59)), 0.8, AND(_xlpm.t>=TIME(0,5,1), _xlpm.t<=TIME(0,6,0)), 0.5, AND(_xlpm.t>=TIME(0,9,0), _xlpm.t<=TIME(0,9,59)), 0.5, TRUE, 0.3 ) )} -> 0.3 | P72: =VALUE(LEFT(I72,1)) -> 0 | Q72: =VALUE(LEFT(J72,1)) -> 0 | R72: =VALUE(LEFT(K72,1)) -> 0 | S72: =VALUE(LEFT(L72,1)) -> 0 | T72: =VALUE(LEFT(M72,1)) -> 0
A73: 24G1118 | B73: 平峯 佑亮 | C73: ハッカソン２ | D73: 39 | E73: 37 | F73: 732講義室 | G73: =SUM($P73:$T73)*$O73 -> 0 | H73: =VLOOKUP($D73,'732講義室'!$B$2:$F$34,2,FALSE) -> 0 | I73: =VLOOKUP($D73,'732講義室'!$B$2:$F$34,3,FALSE) -> 0 | J73: =VLOOKUP($D73,'732講義室'!$B$2:$F$34,4,FALSE) -> 0 | K73: =VLOOKUP($D73,'732講義室'!$B$2:$F$34,5,FALSE) -> 0 | L73: =VLOOKUP($A73,'732講義室'!$G$2:$I$34,3,FALSE) -> 0 | M73: =VLOOKUP($D73,'732講義室'!$B$2:$J$34,9,FALSE) -> 0 | N73: =TIME(0, INT($H73/100), MOD($H73,100)) -> 0 | O73: {=_xlfn.LET( _xlpm.t, TIME(0, INT($H73/100), MOD($H73,100)), _xlfn.IFS( AND(_xlpm.t>=TIME(0,7,1), _xlpm.t<=TIME(0,8,19)), 1, AND(_xlpm.t>=TIME(0,6,1), _xlpm.t<=TIME(0,7,0)), 0.8, AND(_xlpm.t>=TIME(0,8,20), _xlpm.t<=TIME(0,8,59)), 0.8, AND(_xlpm.t>=TIME(0,5,1), _xlpm.t<=TIME(0,6,0)), 0.5, AND(_xlpm.t>=TIME(0,9,0), _xlpm.t<=TIME(0,9,59)), 0.5, TRUE, 0.3 ) )} -> 0.3 | P73: =VALUE(LEFT(I73,1)) -> 0 | Q73: =VALUE(LEFT(J73,1)) -> 0 | R73: =VALUE(LEFT(K73,1)) -> 0 | S73: =VALUE(LEFT(L73,1)) -> 0 | T73: =VALUE(LEFT(M73,1)) -> 0
A74: 24G1013 | B74: 石崎 一葉 | C74: ハッカソン２ | D74: 21 | E74: 36 | F74: 732講義室 | G74: =SUM($P74:$T74)*$O74 -> 0 | H74: =VLOOKUP($D74,'732講義室'!$B$2:$F$34,2,FALSE) -> 0 | I74: =VLOOKUP($D74,'732講義室'!$B$2:$F$34,3,FALSE) -> 0 | J74: =VLOOKUP($D74,'732講義室'!$B$2:$F$34,4,FALSE) -> 0 | K74: =VLOOKUP($D74,'732講義室'!$B$2:$F$34,5,FALSE) -> 0 | L74: =VLOOKUP($A74,'732講義室'!$G$2:$I$34,3,FALSE) -> 0 | M74: =VLOOKUP($D74,'732講義室'!$B$2:$J$34,9,FALSE) -> 0 | N74: =TIME(0, INT($H74/100), MOD($H74,100)) -> 0 | O74: {=_xlfn.LET( _xlpm.t, TIME(0, INT($H74/100), MOD($H74,100)), _xlfn.IFS( AND(_xlpm.t>=TIME(0,7,1), _xlpm.t<=TIME(0,8,19)), 1, AND(_xlpm.t>=TIME(0,6,1), _xlpm.t<=TIME(0,7,0)), 0.8, AND(_xlpm.t>=TIME(0,8,20), _xlpm.t<=TIME(0,8,59)), 0.8, AND(_xlpm.t>=TIME(0,5,1), _xlpm.t<=TIME(0,6,0)), 0.5, AND(_xlpm.t>=TIME(0,9,0), _xlpm.t<=TIME(0,9,59)), 0.5, TRUE, 0.3 ) )} -> 0.3 | P74: =VALUE(LEFT(I74,1)) -> 0 | Q74: =VALUE(LEFT(J74,1)) -> 0 | R74: =VALUE(LEFT(K74,1)) -> 0 | S74: =VALUE(LEFT(L74,1)) -> 0 | T74: =VALUE(LEFT(M74,1)) -> 0
A75: 24G1070 | B75: 重冨 陽人 | C75: ハッカソン２ | D75: 21 | E75: 36 | F75: 732講義室 | G75: =SUM($P75:$T75)*$O75 -> 0 | H75: =VLOOKUP($D75,'732講義室'!$B$2:$F$34,2,FALSE) -> 0 | I75: =VLOOKUP($D75,'732講義室'!$B$2:$F$34,3,FALSE) -> 0 | J75: =VLOOKUP($D75,'732講義室'!$B$2:$F$34,4,FALSE) -> 0 | K75: =VLOOKUP($D75,'732講義室'!$B$2:$F$34,5,FALSE) -> 0 | L75: =VLOOKUP($A75,'732講義室'!$G$2:$I$34,3,FALSE) -> 0 | M75: =VLOOKUP($D75,'732講義室'!$B$2:$J$34,9,FALSE) -> 0 | N75: =TIME(0, INT($H75/100), MOD($H75,100)) -> 0 | O75: {=_xlfn.LET( _xlpm.t, TIME(0, INT($H75/100), MOD($H75,100)), _xlfn.IFS( AND(_xlpm.t>=TIME(0,7,1), _xlpm.t<=TIME(0,8,19)), 1, AND(_xlpm.t>=TIME(0,6,1), _xlpm.t<=TIME(0,7,0)), 0.8, AND(_xlpm.t>=TIME(0,8,20), _xlpm.t<=TIME(0,8,59)), 0.8, AND(_xlpm.t>=TIME(0,5,1), _xlpm.t<=TIME(0,6,0)), 0.5, AND(_xlpm.t>=TIME(0,9,0), _xlpm.t<=TIME(0,9,59)), 0.5, TRUE, 0.3 ) )} -> 0.3 | P75: =VALUE(LEFT(I75,1)) -> 0 | Q75: =VALUE(LEFT(J75,1)) -> 0 | R75: =VALUE(LEFT(K75,1)) -> 0 | S75: =VALUE(LEFT(L75,1)) -> 0 | T75: =VALUE(LEFT(M75,1)) -> 0
A76: 24G1092 | B76: 田中 斗百矢 | C76: ハッカソン２ | D76: 21 | E76: 36 | F76: 732講義室 | G76: =SUM($P76:$T76)*$O76 -> 0 | H76: =VLOOKUP($D76,'732講義室'!$B$2:$F$34,2,FALSE) -> 0 | I76: =VLOOKUP($D76,'732講義室'!$B$2:$F$34,3,FALSE) -> 0 | J76: =VLOOKUP($D76,'732講義室'!$B$2:$F$34,4,FALSE) -> 0 | K76: =VLOOKUP($D76,'732講義室'!$B$2:$F$34,5,FALSE) -> 0 | L76: =VLOOKUP($A76,'732講義室'!$G$2:$I$34,3,FALSE) -> 0 | M76: =VLOOKUP($D76,'732講義室'!$B$2:$J$34,9,FALSE) -> 0 | N76: =TIME(0, INT($H76/100), MOD($H76,100)) -> 0 | O76: {=_xlfn.LET( _xlpm.t, TIME(0, INT($H76/100), MOD($H76,100)), _xlfn.IFS( AND(_xlpm.t>=TIME(0,7,1), _xlpm.t<=TIME(0,8,19)), 1, AND(_xlpm.t>=TIME(0,6,1), _xlpm.t<=TIME(0,7,0)), 0.8, AND(_xlpm.t>=TIME(0,8,20), _xlpm.t<=TIME(0,8,59)), 0.8, AND(_xlpm.t>=TIME(0,5,1), _xlpm.t<=TIME(0,6,0)), 0.5, AND(_xlpm.t>=TIME(0,9,0), _xlpm.t<=TIME(0,9,59)), 0.5, TRUE, 0.3 ) )} -> 0.3 | P76: =VALUE(LEFT(I76,1)) -> 0 | Q76: =VALUE(LEFT(J76,1)) -> 0 | R76: =VALUE(LEFT(K76,1)) -> 0 | S76: =VALUE(LEFT(L76,1)) -> 0 | T76: =VALUE(LEFT(M76,1)) -> 0
A77: 24G1024 | B77: 鵜澤 勇希 | C77: ハッカソン２ | D77: 13 | E77: 29 | F77: 732講義室 | G77: =SUM($P77:$T77)*$O77 -> 0 | H77: =VLOOKUP($D77,'732講義室'!$B$2:$F$34,2,FALSE) -> 0 | I77: =VLOOKUP($D77,'732講義室'!$B$2:$F$34,3,FALSE) -> 0 | J77: =VLOOKUP($D77,'732講義室'!$B$2:$F$34,4,FALSE) -> 0 | K77: =VLOOKUP($D77,'732講義室'!$B$2:$F$34,5,FALSE) -> 0 | L77: =VLOOKUP($A77,'732講義室'!$G$2:$I$34,3,FALSE) -> 0 | M77: =VLOOKUP($D77,'732講義室'!$B$2:$J$34,9,FALSE) -> 0 | N77: =TIME(0, INT($H77/100), MOD($H77,100)) -> 0 | O77: {=_xlfn.LET( _xlpm.t, TIME(0, INT($H77/100), MOD($H77,100)), _xlfn.IFS( AND(_xlpm.t>=TIME(0,7,1), _xlpm.t<=TIME(0,8,19)), 1, AND(_xlpm.t>=TIME(0,6,1), _xlpm.t<=TIME(0,7,0)), 0.8, AND(_xlpm.t>=TIME(0,8,20), _xlpm.t<=TIME(0,8,59)), 0.8, AND(_xlpm.t>=TIME(0,5,1), _xlpm.t<=TIME(0,6,0)), 0.5, AND(_xlpm.t>=TIME(0,9,0), _xlpm.t<=TIME(0,9,59)), 0.5, TRUE, 0.3 ) )} -> 0.3 | P77: =VALUE(LEFT(I77,1)) -> 0 | Q77: =VALUE(LEFT(J77,1)) -> 0 | R77: =VALUE(LEFT(K77,1)) -> 0 | S77: =VALUE(LEFT(L77,1)) -> 0 | T77: =VALUE(LEFT(M77,1)) -> 0
A78: 24G1088 | B78: 武井 佑樹 | C78: ハッカソン２ | D78: 13 | E78: 29 | F78: 732講義室 | G78: =SUM($P78:$T78)*$O78 -> 0 | H78: =VLOOKUP($D78,'732講義室'!$B$2:$F$34,2,FALSE) -> 0 | I78: =VLOOKUP($D78,'732講義室'!$B$2:$F$34,3,FALSE) -> 0 | J78: =VLOOKUP($D78,'732講義室'!$B$2:$F$34,4,FALSE) -> 0 | K78: =VLOOKUP($D78,'732講義室'!$B$2:$F$34,5,FALSE) -> 0 | L78: =VLOOKUP($A78,'732講義室'!$G$2:$I$34,3,FALSE) -> 0 | M78: =VLOOKUP($D78,'732講義室'!$B$2:$J$34,9,FALSE) -> 0 | N78: =TIME(0, INT($H78/100), MOD($H78,100)) -> 0 | O78: {=_xlfn.LET( _xlpm.t, TIME(0, INT($H78/100), MOD($H78,100)), _xlfn.IFS( AND(_xlpm.t>=TIME(0,7,1), _xlpm.t<=TIME(0,8,19)), 1, AND(_xlpm.t>=TIME(0,6,1), _xlpm.t<=TIME(0,7,0)), 0.8, AND(_xlpm.t>=TIME(0,8,20), _xlpm.t<=TIME(0,8,59)), 0.8, AND(_xlpm.t>=TIME(0,5,1), _xlpm.t<=TIME(0,6,0)), 0.5, AND(_xlpm.t>=TIME(0,9,0), _xlpm.t<=TIME(0,9,59)), 0.5, TRUE, 0.3 ) )} -> 0.3 | P78: =VALUE(LEFT(I78,1)) -> 0 | Q78: =VALUE(LEFT(J78,1)) -> 0 | R78: =VALUE(LEFT(K78,1)) -> 0 | S78: =VALUE(LEFT(L78,1)) -> 0 | T78: =VALUE(LEFT(M78,1)) -> 0
A79: 24G1095 | B79: 塚田 快音 | C79: ハッカソン２ | D79: 13 | E79: 29 | F79: 732講義室 | G79: =SUM($P79:$T79)*$O79 -> 0 | H79: =VLOOKUP($D79,'732講義室'!$B$2:$F$34,2,FALSE) -> 0 | I79: =VLOOKUP($D79,'732講義室'!$B$2:$F$34,3,FALSE) -> 0 | J79: =VLOOKUP($D79,'732講義室'!$B$2:$F$34,4,FALSE) -> 0 | K79: =VLOOKUP($D79,'732講義室'!$B$2:$F$34,5,FALSE) -> 0 | L79: =VLOOKUP($A79,'732講義室'!$G$2:$I$34,3,FALSE) -> 0 | M79: =VLOOKUP($D79,'732講義室'!$B$2:$J$34,9,FALSE) -> 0 | N79: =TIME(0, INT($H79/100), MOD($H79,100)) -> 0 | O79: {=_xlfn.LET( _xlpm.t, TIME(0, INT($H79/100), MOD($H79,100)), _xlfn.IFS( AND(_xlpm.t>=TIME(0,7,1), _xlpm.t<=TIME(0,8,19)), 1, AND(_xlpm.t>=TIME(0,6,1), _xlpm.t<=TIME(0,7,0)), 0.8, AND(_xlpm.t>=TIME(0,8,20), _xlpm.t<=TIME(0,8,59)), 0.8, AND(_xlpm.t>=TIME(0,5,1), _xlpm.t<=TIME(0,6,0)), 0.5, AND(_xlpm.t>=TIME(0,9,0), _xlpm.t<=TIME(0,9,59)), 0.5, TRUE, 0.3 ) )} -> 0.3 | P79: =VALUE(LEFT(I79,1)) -> 0 | Q79: =VALUE(LEFT(J79,1)) -> 0 | R79: =VALUE(LEFT(K79,1)) -> 0 | S79: =VALUE(LEFT(L79,1)) -> 0 | T79: =VALUE(LEFT(M79,1)) -> 0
... A100: 24G1084 | B100: 関屋 咲希 | C100: ハッカソン２ | D100: 17 | E100: 4 | F100: 732講義室 | G100: =SUM($P100:$T100)*$O100 -> 0 | H100: =VLOOKUP($D100,'732講義室'!$B$2:$F$34,2,FALSE) -> 0 | I100: =VLOOKUP($D100,'732講義室'!$B$2:$F$34,3,FALSE) -> 0 | J100: =VLOOKUP($D100,'732講義室'!$B$2:$F$34,4,FALSE) -> 0 | K100: =VLOOKUP($D100,'732講義室'!$B$2:$F$34,5,FALSE) -> 0 | L100: =VLOOKUP($A100,'732講義室'!$G$2:$I$34,3,FALSE) -> 0 | M100: =VLOOKUP($D100,'732講義室'!$B$2:$J$34,9,FALSE) -> 0 | N100: =TIME(0, INT($H100/100), MOD($H100,100)) -> 0 | O100: {=_xlfn.LET( _xlpm.t, TIME(0, INT($H100/100), MOD($H100,100)), _xlfn.IFS( AND(_xlpm.t>=TIME(0,7,1), _xlpm.t<=TIME(0,8,19)), 1, AND(_xlpm.t>=TIME(0,6,1), _xlpm.t<=TIME(0,7,0)), 0.8, AND(_xlpm.t>=TIME(0,8,20), _xlpm.t<=TIME(0,8,59)), 0.8, AND(_xlpm.t>=TIME(0,5,1), _xlpm.t<=TIME(0,6,0)), 0.5, AND(_xlpm.t>=TIME(0,9,0), _xlpm.t<=TIME(0,9,59)), 0.5, TRUE, 0.3 ) )} -> 0.3 | P100: =VALUE(LEFT(I100,1)) -> 0 | Q100: =VALUE(LEFT(J100,1)) -> 0 | R100: =VALUE(LEFT(K100,1)) -> 0 | S100: =VALUE(LEFT(L100,1)) -> 0 | T100: =VALUE(LEFT(M100,1)) -> 0
...

Sheet 発表順
A1: チーム | B1: 講義室 | C1: 題目 | D1: 発表順番用(降順)
A2: 16 | B2: 722講義室 | C2: 脈拍でテンポが変化するオーケストラ | D2: 41
A3: 34 | B3: 722講義室 | C3: 君が指揮する_x000D_ Arduinoオーケストラ | D3: 38
A4: 14 | B4: 722講義室 | C4: 害獣対策機能を備えた接近応答型Arduino同期演奏システム | D4: 35
A5: 32 | B5: 722講義室 | C5: 指揮者人形による自律同期Arduinoオーケストラ | D5: 30
A6: 25 | B6: 722講義室 | C6: カウントイン信号を用いたArduinoオーケストラの提案 | D6: 27
A7: 24 | B7: 722講義室 | C7: LED鍵盤を用いて視覚的に理解できる合奏システム | D7: 22
A8: 1 | B8: 722講義室 | C8: 光の点滅同期オーケストラ | D8: 19
A9: 29 | B9: 722講義室 | C9: マトリクスメトロノームによる Arduino オーケストラ | D9: 14
A10: 19 | B10: 722講義室 | C10: 赤外線通信を用いたズレの少ないオーケストラ演奏システムの作成 | D10: 11
A11: 12 | B11: 722講義室 | C11: 現代の音楽鑑賞での視覚情報の欠如に伴う没入感の低下を解消するために演奏動作の模倣とI2C通信の演奏同期による生演奏感を提供するArduinoオーケストラ | D11: 6
A12: 26 | B12: 722講義室 | C12: 単一のフルカラーLEDとArduinoを用いた光無線通信による楽器間同期演奏システム | D12: 3
A13: 10 | B13: 731講義室 | C13: 光を用いた輪奏システム_x000D_ ~カエルの歌で奏でるアンサンブル~ | D13: 40
... A15: 33 | B15: 731講義室 | C15: 光信号を用いて各楽器を同期させよう | D15: 34
A16: 42 | B16: 731講義室 | D16: 31
A17: 41 | B17: 731講義室 | C17: Froguino（フログイーノ） ~カエルの歌輪唱システム~_x000D_ | D17: 26
A18: 22 | B18: 731講義室 | C18: 周波数を用いたリズム同期システムのArduinoオーケストラ | D18: 23
A19: 3 | B19: 731講義室 | C19: 音階対応LED表示機能を用いた楽器間同期演奏システム | D19: 18
A20: 27 | B20: 731講義室 | C20: RGB LEDの発光状態を利用した楽器間同期演奏システム | D20: 15
A21: 31 | B21: 731講義室 | C21: メリーゴーラウンド型輪唱システム | D21: 10
A22: 7 | B22: 731講義室 | C22: LED同期を用いた輪唱曲演奏システム | D22: 7
A23: 4 | B23: 731講義室 | C23: 受動的環境介入によるメンタルヘルス支援：大学空間における自動演奏装置の提案 | D23: 2
A24: 28 | B24: 732講義室 | C24: 無線通信を用いた時刻同期Arduinoオーケストラ | D24: 42
A25: 39 | B25: 732講義室 | C25: 要介護者も楽しめる輪唱・オーケストラ | D25: 37
A26: 21 | B26: 732講義室 | C26: 有線接続による低遅延リアルタイム演奏システム | D26: 36
A27: 13 | B27: 732講義室 | C27: 赤外線同期及び複数Arduinoによる演奏・照明演出システム | D27: 29
A28: 8 | B28: 732講義室 | C28: 可視光通信とスペクトル表示を用いた同期演奏システム | D28: 28
... A45: 43 | B45: 733演習室 | C45: ピタゴラ伝言ゲーム | D45: 43

Sheet プルダウン用隠し
A1: 評価
A2: 3(A)
A3: 2(B)
A4: 1(C)
A5: 0(D)
